Exception:
Traceback (most recent call last):
  File "/usr/lib/python2.6/dist-packages/pip.py", line 252, in main
    self.run(options, args)
  File "/usr/lib/python2.6/dist-packages/pip.py", line 401, in run
    InstallRequirement.from_line(name, None))
  File "/usr/lib/python2.6/dist-packages/pip.py", line 1228, in from_line
    return cls(req, comes_from, url=url)
  File "/usr/lib/python2.6/dist-packages/pip.py", line 1185, in __init__
    req = pkg_resources.Requirement.parse(req)
  File "/usr/local/lib/python2.6/dist-packages/setuptools-0.6c11-py2.6.egg/pkg_resources.py", line 2510, in parse
    reqs = list(parse_requirements(s))
  File "/usr/local/lib/python2.6/dist-packages/setuptools-0.6c11-py2.6.egg/pkg_resources.py", line 2436, in parse_requirements
    line, p, specs = scan_list(VERSION,LINE_END,line,p,(1,2),"version spec")
  File "/usr/local/lib/python2.6/dist-packages/setuptools-0.6c11-py2.6.egg/pkg_resources.py", line 2404, in scan_list
    raise ValueError("Expected "+item_name+" in",line,"at",line[p:])
ValueError: ('Expected version spec in', 'django-mptt,', 'at', ',')
